Workbook

Sheet Sheet1
B1: 0 | C1: 0.0037813559 | D1: 0.0075627119 | E1: 0.011344068 | F1: 0.015125424 | G1: 0.01890678 | H1: 0.022688136 | I1: 0.026469492 | J1: 0.030250847 | K1: 0.034032203 | L1: 0.037813559 | M1: 0.041594915 | N1: 0.045376271 | O1: 0.049157627 | P1: 0.052938983 | Q1: 0.056720339 | R1: 0.060501695 | S1: 0.064283051 | T1: 0.068064407 | U1: 0.071845763 | V1: 0.075627119 | W1: 0.079408475 | X1: 0.083189831 | Y1: 0.086971186 | Z1: 0.090752542 | AA1: 0.094533898 | AB1: 0.098315254 | AC1: 0.10209661 | AD1: 0.10587797 | AE1: 0.10965932 | AF1: 0.11344068 | AG1: 0.11722203 | AH1: 0.12100339 | AI1: 0.12478475 | AJ1: 0.1285661 | AK1: 0.13234746 | AL1: 0.13612881 | AM1: 0.13991017 | AN1: 0.14369153 | AO1: 0.14747288 | AP1: 0.15125424 | AQ1: 0.15503559 | AR1: 0.15881695 | AS1: 0.16259831 | AT1: 0.16637966 | AU1: 0.17016102 | AV1: 0.17394237 | AW1: 0.17772373 | AX1: 0.18150508 | AY1: 0.18528644 | AZ1: 0.1890678 | BA1: 0.19284915 | BB1: 0.19663051 | BC1: 0.20041186 | BD1: 0.20419322 | BE1: 0.20797458 | BF1: 0.21175593 | BG1: 0.21553729 | BH1: 0.21931864 | BI1: 0.2231 | BJ1: 0.22688136 | BK1: 0.23066271 | BL1: 0.23444407 | BM1: 0.23822542 | BN1: 0.24200678 | BO1: 0.24578814 | BP1: 0.24956949 | BQ1: 0.25335085 | BR1: 0.2571322 | BS1: 0.26091356 | BT1: 0.26469492 | BU1: 0.26847627 | BV1: 0.27225763 | BW1: 0.27603898 | BX1: 0.27982034 | BY1: 0.28360169 | BZ1: 0.28738305 | CA1: 0.29116441 | CB1: 0.29494576 | CC1: 0.29872712 | CD1: 0.30250847 | CE1: 0.30628983 | CF1: 0.31007119 | CG1: 0.31385254 | CH1: 0.3176339 | CI1: 0.32141525 | CJ1: 0.32519661 | CK1: 0.32897797 | CL1: 0.33275932 | CM1: 0.33654068 | CN1: 0.34032203 | CO1: 0.34410339 | CP1: 0.34788475 | CQ1: 0.3516661 | CR1: 0.35544746 | CS1: 0.35922881 | CT1: 0.36301017 | CU1: 0.36679153 | CV1: 0.37057288 | CW1: 0.37435424 | CX1: 0.37813559 | CY1: 0.38191695 | CZ1: 0.38569831 | DA1: 0.38947966 | DB1: 0.39326102 | DC1: 0.39704237 | DD1: 0.40082373 | DE1: 0.40460508 | DF1: 0.40838644 | DG1: 0.4121678 | DH1: 0.41594915 | DI1: 0.41973051 | DJ1: 0.42351186 | DK1: 0.42729322 | DL1: 0.43107458 | DM1: 0.43485593 | DN1: 0.43863729 | DO1: 0.44241864 | DP1: 0.4462
A2: 0 | B2: 0.0181263 | C2: 0.0211045 | D2: 0.0213688 | E2: 0.0216786 | F2: 0.0220339 | G2: 0.0224347 | H2: 0.022881 | I2: 0.0259052 | J2: 0.0262569 | K2: 0.0266571 | L2: 0.0271059 | M2: 0.0277176 | N2: 0.0283668 | O2: 0.0315328 | P2: 0.0321007 | Q2: 0.032725 | R2: 0.0334056 | S2: 0.0341426 | T2: 0.0349359 | U2: 0.0357856 | V2: 0.0385572 | W2: 0.0192151 | X2: 0.0189459 | Y2: 0.0188451 | Z2: 0.0211929 | AA2: 0.0210046 | AB2: 0.0210158 | AC2: 0.0232745 | AD2: 0.0231872 | AE2: 0.0256118 | AF2: 0.0254547 | AG2: 0.0254745 | AH2: 0.027784 | AI2: 0.0277126 | AJ2: 0.0302032 | AK2: 0.0300433 | AL2: 0.0300614 | AM2: 0.0324369 | AN2: 0.0323866 | AO2: 0.0325083 | AP2: 0.0347976 | AQ2: 0.0348342 | AR2: 0.037334 | AS2: 0.0372874 | AT2: 0.037415 | AU2: 0.0398246 | AV2: 0.0398837 | AW2: 0.0401103 | AX2: 0.0424328 | AY2: 0.0425697 | AZ2: 0.0450954 | BA2: 0.0451454 | BB2: 0.0453664 | BC2: 0.0478101 | BD2: 0.0479647 | BE2: 0.0482853 | BF2: 0.0506749 | BG2: 0.0509113 | BH2: 0.0535346 | BI2: 0.0536872 | BJ2: 0.0540101 | BK2: 0.0565672 | BL2: 0.0568203 | BM2: 0.0572381 | BN2: 0.0597331 | BO2: 0.0600599 | BP2: 0.0605698 | BQ2: 0.0630254 | BR2: 0.063436 | BS2: 0.0661115 | BT2: 0.0664556 | BU2: 0.066967 | BV2: 0.0696225 | BW2: 0.0700485 | BX2: 0.0706615 | BY2: 0.0733147 | BZ2: 0.0738298 | CA2: 0.0745186 | CB2: 0.0771625 | CC2: 0.077776 | CD2: 0.0785451 | CE2: 0.0811569 | CF2: 0.0818685 | CG2: 0.0847269 | CH2: 0.0853388 | CI2: 0.0861295 | CJ2: 0.089011 | CK2: 0.0897328 | CL2: 0.0906184 | CM2: 0.0935188 | CN2: 0.0943532 | CO2: 0.0953485 | CP2: 0.0982812 | CQ2: 0.0992027 | CR2: 0.100307 | CS2: 0.103281 | CT2: 0.104301 | CU2: 0.105492 | CV2: 0.108517 | CW2: 0.109654 | CX2: 0.110949 | CY2: 0.114029 | CZ2: 0.115292 | DA2: 0.116714 | DB2: 0.119885 | DC2: 0.121256 | DD2: 0.122809 | DE2: 0.126082 | DF2: 0.127573 | DG2: 0.129235 | DH2: 0.132597 | DI2: 0.134221 | DJ2: 0.136007 | DK2: 0.139455 | DL2: 0.141231 | DM2: 0.14318 | DN2: 0.146826 | DO2: 0.148757 | DP2: 0.150877
A3: 0.0020063025 | B3: 0.020884903 | C3: 0.024812348 | D3: 0.024873097 | E3: 0.024982438 | F3: 0.025140171 | G3: 0.025346498 | H3: 0.025601217 | I3: 0.029570179 | J3: 0.029714231 | K3: 0.029907377 | L3: 0.030149618 | M3: 0.03056524 | N3: 0.031020556 | O3: 0.035142842 | P3: 0.035504994 | Q3: 0.035926339 | R3: 0.036407178 | S3: 0.036947211 | T3: 0.037546538 | U3: 0.038205258 | V3: 0.042094726 | W3: 0.0229948 | X3: 0.022189668 | Y3: 0.021589986 | Z3: 0.024728769 | AA3: 0.024021561 | AB3: 0.023549498 | AC3: 0.026576449 | AD3: 0.025986963 | AE3: 0.029207546 | AF3: 0.028526229 | AG3: 0.028057158 | AH3: 0.031143016 | AI3: 0.030559715 | AJ3: 0.033862519 | AK3: 0.0331755 | AL3: 0.032701227 | AM3: 0.03587692 | AN3: 0.03531372 | AO3: 0.034959169 | AP3: 0.038036949 | AQ3: 0.037573466 | AR3: 0.040897289 | AS3: 0.040331181 | AT3: 0.039974518 | AU3: 0.043184507 | AV3: 0.042734711 | AW3: 0.042489464 | AX3: 0.04559523 | AY3: 0.045234649 | AZ3: 0.048587974 | BA3: 0.048122171 | BB3: 0.047863616 | BC3: 0.051124232 | BD3: 0.050776046 | BE3: 0.050631511 | BF3: 0.053826512 | BG3: 0.053570239 | BH3: 0.05703949 | BI3: 0.056676988 | BJ3: 0.056520333 | BK3: 0.059901451 | BL3: 0.05964856 | BM3: 0.059597618 | BN3: 0.06290412 | BO3: 0.062734443 | BP3: 0.062788419 | BQ3: 0.066047213 | BR3: 0.065977059 | BS3: 0.069510428 | BT3: 0.06934854 | BU3: 0.069390901 | BV3: 0.072895959 | BW3: 0.072822981 | BX3: 0.072976154 | BY3: 0.076460783 | BZ3: 0.076486917 | CA3: 0.076721396 | CB3: 0.080180399 | CC3: 0.080313043 | CD3: 0.080639138 | CE3: 0.084055729 | CF3: 0.084296688 | CG3: 0.088025771 | CH3: 0.088140697 | CI3: 0.088468668 | CJ3: 0.092220253 | CK3: 0.09245349 | CL3: 0.092887076 | CM3: 0.096647045 | CN3: 0.096998588 | CO3: 0.09754808 | CP3: 0.10132973 | CQ3: 0.10177007 | CR3: 0.10243447 | CS3: 0.10624961 | CT3: 0.10679797 | CU3: 0.10755337 | CV3: 0.11142252 | CW3: 0.11209589 | CX3: 0.11296531 | CY3: 0.11689346 | CZ3: 0.11769984 | DA3: 0.11870128 | DB3: 0.12271642 | DC3: 0.1236298 | DD3: 0.12476523 | DE3: 0.12886935 | DF3: 0.12990474 | DG3: 0.13114616 | DH3: 0.13533728 | DI3: 0.13651266 | DJ3: 0.1378861 | DK3: 0.14219125 | DL3: 0.14353066 | DM3: 0.14508512 | DN3: 0.14965637 | DO3: 0.1511718 | DP3: 0.15291429
A4: 0.004012605 | B4: 0.024800306 | C4: 0.029735897 | D4: 0.029585593 | E4: 0.029484476 | F4: 0.029432343 | G4: 0.029429295 | H4: 0.029475235 | I4: 0.034458358 | J4: 0.034388962 | K4: 0.034366854 | L4: 0.034392035 | M4: 0.03459658 | N4: 0.034840111 | O4: 0.040014584 | P4: 0.040168287 | Q4: 0.040382578 | R4: 0.040657256 | S4: 0.040992422 | T4: 0.041388075 | U4: 0.041844215 | V4: 0.047010251 | W4: 0.028240201 | X4: 0.026838837 | Y4: 0.025668671 | Z4: 0.029710938 | AA4: 0.028419221 | AB4: 0.027384196 | AC4: 0.031299198 | AD4: 0.030135426 | AE4: 0.034263192 | AF4: 0.032991058 | AG4: 0.031954116 | AH4: 0.035941531 | AI4: 0.03477523 | AJ4: 0.039006837 | AK4: 0.0377283 | AL4: 0.036685255 | AM4: 0.04078854 | AN4: 0.039640541 | AO4: 0.038726638 | AP4: 0.042727298 | AQ4: 0.041686233 | AR4: 0.045955678 | AS4: 0.044798962 | AT4: 0.043875537 | AU4: 0.048018114 | AV4: 0.046982622 | AW4: 0.046178428 | AX4: 0.05021216 | AY4: 0.049274198 | AZ4: 0.053590247 | BA4: 0.052535642 | BB4: 0.051713832 | BC4: 0.055934763 | BD4: 0.055004392 | BE4: 0.054305021 | BF4: 0.058453823 | BG4: 0.057621179 | BH4: 0.062071979 | BI4: 0.061117376 | BJ4: 0.060394166 | BK4: 0.064745302 | BL4: 0.06390522 | BM4: 0.063294937 | BN4: 0.06757054 | BO4: 0.066821185 | BP4: 0.066325238 | BQ4: 0.070552226 | BR4: 0.069915217 | BS4: 0.074459255 | BT4: 0.07370998 | BU4: 0.073192103 | BV4: 0.077702819 | BW4: 0.077046162 | BX4: 0.076644008 | BY4: 0.081120765 | BZ4: 0.080571033 | CA4: 0.080254391 | CB4: 0.084697497 | CC4: 0.084259986 | CD4: 0.084046077 | CE4: 0.088446358 | CF4: 0.088124776 | CG4: 0.092893041 | CH4: 0.092427693 | CI4: 0.092199336 | CJ4: 0.096990306 | CK4: 0.09664748 | CL4: 0.096533153 | CM4: 0.10132469 | CN4: 0.10110238 | CO4: 0.10110716 | CP4: 0.10591446 | CQ4: 0.10578415 | CR4: 0.10590795 | CS4: 0.11075022 | CT4: 0.11073694 | CU4: 0.11095674 | CV4: 0.11586204 | CW4: 0.11597978 | CX4: 0.11632262 | CY4: 0.12128893 | CZ4: 0.12154169 | DA4: 0.12202055 | DB4: 0.12706884 | DC4: 0.12742661 | DD4: 0.12804047 | DE4: 0.13316771 | DF4: 0.13365247 | DG4: 0.13437133 | DH4: 0.13959955 | DI4: 0.14023233 | DJ4: 0.1410962 | DK4: 0.1464855 | DL4: 0.14730132 | DM4: 0.14836624 | DN4: 0.15410374 | DO4: 0.15511961 | DP4: 0.15639159
A5: 0.0060189076 | B5: 0.029936109 | C5: 0.035867645 | D5: 0.03551489 | E5: 0.035209214 | F5: 0.034950914 | G5: 0.034739793 | H5: 0.034575952 | I5: 0.040575036 | J5: 0.040303594 | K5: 0.040075931 | L5: 0.039892053 | M5: 0.03988942 | N5: 0.039922167 | O5: 0.046181526 | P5: 0.046143881 | Q5: 0.046166418 | R5: 0.046248934 | S5: 0.046391633 | T5: 0.046594413 | U5: 0.046857273 | V5: 0.053382277 | W5: 0.035041501 | X5: 0.033021905 | Y5: 0.031244757 | Z5: 0.036248007 | AA5: 0.034342882 | AB5: 0.032699494 | AC5: 0.037570547 | AD5: 0.035795488 | AE5: 0.040889138 | AF5: 0.038996888 | AG5: 0.037348375 | AH5: 0.042310847 | AI5: 0.040526645 | AJ5: 0.045749356 | AK5: 0.043851801 | AL5: 0.042197982 | AM5: 0.047301361 | AN5: 0.045532761 | AO5: 0.044009007 | AP5: 0.049013047 | AQ5: 0.047352099 | AR5: 0.052633567 | AS5: 0.050851943 | AT5: 0.049313155 | AU5: 0.054468621 | AV5: 0.052806933 | AW5: 0.051389092 | AX5: 0.056444489 | AY5: 0.054884147 | AZ5: 0.060242921 | BA5: 0.058562413 | BB5: 0.057125949 | BC5: 0.062395495 | BD5: 0.060838237 | BE5: 0.059525532 | BF5: 0.064723235 | BG5: 0.063264518 | BH5: 0.068776869 | BI5: 0.067189663 | BJ5: 0.0658455 | BK5: 0.071260053 | BL5: 0.06978738 | BM5: 0.068558555 | BN5: 0.073908961 | BO5: 0.072531128 | BP5: 0.071421157 | BQ5: 0.07672934 | BR5: 0.075471276 | BS5: 0.081121183 | BT5: 0.07973772 | BU5: 0.078599304 | BV5: 0.084216278 | BW5: 0.082925443 | BX5: 0.081902561 | BY5: 0.087480448 | BZ5: 0.08630125 | CA5: 0.085366387 | CB5: 0.090913496 | CC5: 0.089848629 | CD5: 0.089025815 | CE5: 0.094539688 | CF5: 0.093594264 | CG5: 0.099513212 | CH5: 0.09841739 | CI5: 0.097568604 | CJ5: 0.10351186 | CK5: 0.10253787 | CL5: 0.10180803 | CM5: 0.10774853 | CN5: 0.10689356 | CO5: 0.10628374 | CP5: 0.11224619 | CQ5: 0.11148522 | CR5: 0.11099642 | CS5: 0.11700183 | CT5: 0.11636591 | CU5: 0.11597812 | CV5: 0.12205856 | CW5: 0.12155567 | CX5: 0.12129793 | CY5: 0.12744039 | CZ5: 0.12707153 | DA5: 0.12694983 | DB5: 0.13316927 | DC5: 0.13290441 | DD5: 0.1329147 | DE5: 0.13921406 | DF5: 0.13908321 | DG5: 0.13920249 | DH5: 0.14563483 | DI5: 0.14566399 | DJ5: 0.1459473 | DK5: 0.15260574 | DL5: 0.15283598 | DM5: 0.15334136 | DN5: 0.16043911 | DO5: 0.16089741 | DP5: 0.16163088
A6: 0.0080252101 | B6: 0.036269512 | C6: 0.043123894 | D6: 0.042589987 | E6: 0.042099852 | F6: 0.041653485 | G6: 0.041250791 | H6: 0.04089187 | I6: 0.047849715 | J6: 0.047402225 | K6: 0.046994509 | L6: 0.04662647 | M6: 0.04643876 | N6: 0.046280922 | O6: 0.053599468 | P6: 0.053404275 | Q6: 0.053267957 | R6: 0.053190612 | S6: 0.053172244 | T6: 0.05321275 | U6: 0.053312131 | V6: 0.061199702 | W6: 0.043395402 | X6: 0.040773173 | Y6: 0.038389843 | Z6: 0.044354076 | AA6: 0.041844042 | AB6: 0.039585292 | AC6: 0.045424096 | AD6: 0.043038751 | AE6: 0.049101884 | AF6: 0.046598817 | AG6: 0.044333233 | AH6: 0.050286762 | AI6: 0.047888561 | AJ6: 0.054106675 | AK6: 0.051600001 | AL6: 0.049330709 | AM6: 0.055446481 | AN6: 0.053059982 | AO6: 0.050913976 | AP6: 0.056941097 | AQ6: 0.054656966 | AR6: 0.060958056 | AS6: 0.058555724 | AT6: 0.056391774 | AU6: 0.062581128 | AV6: 0.060292545 | AW6: 0.058245556 | AX6: 0.064355019 | AY6: 0.062166596 | AZ6: 0.068585594 | BA6: 0.066280584 | BB6: 0.064216265 | BC6: 0.070558526 | BD6: 0.068369383 | BE6: 0.066422943 | BF6: 0.072701046 | BG6: 0.070606458 | BH6: 0.077198159 | BI6: 0.074977451 | BJ6: 0.072997133 | BK6: 0.079506304 | BL6: 0.077395739 | BM6: 0.075528674 | BN6: 0.081994581 | BO6: 0.079979171 | BP6: 0.078229476 | BQ6: 0.084665653 | BR6: 0.082770834 | BS6: 0.089553811 | BT6: 0.08752946 | BU6: 0.085749006 | BV6: 0.092505638 | BW6: 0.090570724 | BX6: 0.088901215 | BY6: 0.09562453 | BZ6: 0.093802066 | CA6: 0.092221182 | CB6: 0.098927095 | CC6: 0.097217672 | CD6: 0.095754154 | CE6: 0.10244412 | CF6: 0.10085355 | CG6: 0.10796328 | CH6: 0.10622559 | CI6: 0.10473107 | CJ6: 0.11186981 | CK6: 0.11024816 | CL6: 0.10887371 | CM6: 0.11601438 | CN6: 0.11450875 | CO6: 0.11325232 | CP6: 0.12042792 | CQ6: 0.1190183 | CR6: 0.11788389 | CS6: 0.12511945 | CT6: 0.12383887 | CU6: 0.12280749 | CV6: 0.13013008 | CW6: 0.12898055 | CX6: 0.12808324 | CY6: 0.13546786 | CZ6: 0.13444938 | DA6: 0.1336821 | DB6: 0.14114469 | DC6: 0.14022821 | DD6: 0.13959293 | DE6: 0.14715141 | DF6: 0.14637794 | DG6: 0.14585966 | DH6: 0.1536021 | DI6: 0.15300366 | DJ6: 0.1526704 | DK6: 0.16071799 | DL6: 0.16034164 | DM6: 0.16025148 | DN6: 0.16882848 | DO6: 0.16870722 | DP6: 0.16886618
A7: 0.010031513 | B7: 0.043704015 | C7: 0.051371742 | D7: 0.050685883 | E7: 0.05003969 | F7: 0.049433156 | G7: 0.048866388 | H7: 0.048339387 | I7: 0.056162994 | J7: 0.055574156 | K7: 0.055021786 | L7: 0.054506188 | M7: 0.0541692 | N7: 0.053856078 | O7: 0.06216961 | P7: 0.061860869 | Q7: 0.061610296 | R7: 0.06141789 | S7: 0.061283555 | T7: 0.061207388 | U7: 0.061189288 | V7: 0.070378828 | W7: 0.053223202 | X7: 0.050041641 | Y7: 0.047083929 | Z7: 0.053963245 | AA7: 0.050885703 | AB7: 0.048038891 | AC7: 0.054809445 | AD7: 0.051845914 | AE7: 0.05883743 | AF7: 0.055762746 | AG7: 0.052908691 | AH7: 0.059818978 | AI7: 0.056841976 | AJ7: 0.064012693 | AK7: 0.060935201 | AL7: 0.058078337 | AM7: 0.065167001 | AN7: 0.062197102 | AO7: 0.059451545 | AP7: 0.066467146 | AQ7: 0.063590132 | AR7: 0.070869645 | AS7: 0.067882604 | AT7: 0.065118292 | AU7: 0.072310135 | AV7: 0.069427656 | AW7: 0.06677252 | AX7: 0.073911049 | AY7: 0.071123345 | AZ7: 0.078565368 | BA7: 0.075669055 | BB7: 0.072998681 | BC7: 0.080379958 | BD7: 0.077588329 | BE7: 0.075025354 | BF7: 0.082355958 | BG7: 0.079651497 | BH7: 0.087286249 | BI7: 0.084464939 | BJ7: 0.081870166 | BK7: 0.089446755 | BL7: 0.086728899 | BM7: 0.084241492 | BN7: 0.091800701 | BO7: 0.089174313 | BP7: 0.086798195 | BQ7: 0.094343666 | BR7: 0.091832393 | BS7: 0.099713539 | BT7: 0.0970773 | BU7: 0.094671407 | BV7: 0.1025383 | BW7: 0.099986104 | BX7: 0.097683969 | BY7: 0.10553341 | BZ7: 0.10309108 | CA7: 0.10087598 | CB7: 0.10873049 | CC7: 0.10639622 | CD7: 0.10430019 | CE7: 0.11215965 | CF7: 0.10993944 | CG7: 0.11821235 | CH7: 0.11585698 | CI7: 0.11373084 | CJ7: 0.12203876 | CK7: 0.11979345 | CL7: 0.11778338 | CM7: 0.12610622 | CN7: 0.12397194 | CO7: 0.1220759 | CP7: 0.13045664 | CQ7: 0.12841837 | CR7: 0.12664337 | CS7: 0.13510206 | CT7: 0.13319484 | CU7: 0.13152386 | CV7: 0.14007759 | CW7: 0.13829644 | CX7: 0.13675754 | CY7: 0.14537532 | CZ7: 0.14371722 | DA7: 0.14230438 | DB7: 0.15100911 | DC7: 0.14945501 | DD7: 0.14817417 | DE7: 0.15700876 | DF7: 0.15560968 | DG7: 0.15445882 | DH7: 0.16354338 | DI7: 0.16233632 | DJ7: 0.1613925 | DK7: 0.17086924 | DL7: 0.1699053 | DM7: 0.1692246 | DN7: 0.17931385 | DO7: 0.17862802 | DP7: 0.17821647
A8: 0.012037815 | B8: 0.052100818 | C8: 0.060469891 | D8: 0.05966108 | E8: 0.058888828 | F8: 0.058153228 | G8: 0.057454286 | H8: 0.056791904 | I8: 0.065385673 | J8: 0.064690987 | K8: 0.064032063 | L8: 0.063408806 | M8: 0.06296464 | N8: 0.062539633 | O8: 0.071774952 | P8: 0.071398662 | Q8: 0.071081335 | R8: 0.070822768 | S8: 0.070623165 | T8: 0.070482525 | U8: 0.070400746 | V8: 0.080799853 | W8: 0.064407603 | X8: 0.06072121 | Y8: 0.057237914 | Z8: 0.064963113 | AA8: 0.061369163 | AB8: 0.057982789 | AC8: 0.065621694 | AD8: 0.062129177 | AE8: 0.069985376 | AF8: 0.066392175 | AG8: 0.062998449 | AH8: 0.070801793 | AI8: 0.067296991 | AJ8: 0.075353212 | AK8: 0.071755801 | AL8: 0.068358464 | AM8: 0.076351221 | AN8: 0.072848722 | AO8: 0.069549313 | AP8: 0.077486195 | AQ8: 0.074065898 | AR8: 0.082257234 | AS8: 0.078736685 | AT8: 0.075419011 | AU8: 0.083550242 | AV8: 0.080125567 | AW8: 0.076907684 | AX8: 0.085011879 | AY8: 0.081674094 | AZ8: 0.090069841 | BA8: 0.086632126 | BB8: 0.083400097 | BC8: 0.091750889 | BD8: 0.088406275 | BE8: 0.085269964 | BF8: 0.093586469 | BG8: 0.090320737 | BH8: 0.098931338 | BI8: 0.095560427 | BJ8: 0.092396799 | BK8: 0.10097691 | BL8: 0.097702659 | BM8: 0.094639311 | BN8: 0.10322652 | BO8: 0.10003746 | BP8: 0.097076713 | BQ8: 0.10566628 | BR8: 0.10258235 | BS8: 0.11148837 | BT8: 0.10829024 | BU8: 0.10530241 | BV8: 0.11420936 | BW8: 0.11108829 | BX8: 0.10819752 | BY8: 0.1171103 | BZ8: 0.1140943 | CA8: 0.11128857 | CB8: 0.12023019 | CC8: 0.11731826 | CD8: 0.11462563 | CE8: 0.12359418 | CF8: 0.12078933 | CG8: 0.13015142 | CH8: 0.12722438 | CI8: 0.12450761 | CJ8: 0.13391472 | CK8: 0.13109074 | CL8: 0.12848606 | CM8: 0.13792507 | CN8: 0.13521013 | CO8: 0.13271548 | CP8: 0.14223537 | CQ8: 0.13961645 | CR8: 0.13724084 | CS8: 0.14685767 | CT8: 0.14436481 | CU8: 0.14209123 | CV8: 0.15180811 | CW8: 0.14943533 | CX8: 0.14728785 | CY8: 0.15707079 | CZ8: 0.15481707 | DA8: 0.15279165 | DB8: 0.16268253 | DC8: 0.16053582 | DD8: 0.1586484 | DE8: 0.16872012 | DF8: 0.16674341 | DG8: 0.16500098 | DH8: 0.17540065 | DI8: 0.17363498 | DJ8: 0.17212261 | DK8: 0.18300149 | DL8: 0.18149896 | DM8: 0.18026572 | DN8: 0.19182522 | DO8: 0.19061883 | DP8: 0.18967376
A9: 0.014044118 | B9: 0.061319621 | C9: 0.070308239 | D9: 0.069399277 | E9: 0.068525966 | F9: 0.067688299 | G9: 0.066886384 | H9: 0.066120122 | I9: 0.075418652 | J9: 0.074648119 | K9: 0.07391524 | L9: 0.073220023 | M9: 0.07270838 | N9: 0.072214189 | O9: 0.082320894 | P9: 0.081916256 | Q9: 0.081573974 | R9: 0.081293846 | S9: 0.081075976 | T9: 0.080920363 | U9: 0.080826904 | V9: 0.092349779 | W9: 0.076839003 | X9: 0.072694178 | Y9: 0.068733 | Z9: 0.077240582 | AA9: 0.073176224 | AB9: 0.069301787 | AC9: 0.077746143 | AD9: 0.07377244 | AE9: 0.082435222 | AF9: 0.078370704 | AG9: 0.074487907 | AH9: 0.083119409 | AI9: 0.079134806 | AJ9: 0.088014731 | AK9: 0.083941501 | AL9: 0.080051091 | AM9: 0.088880741 | AN9: 0.084893143 | AO9: 0.081089982 | AP9: 0.089878844 | AQ9: 0.085964665 | AR9: 0.095006324 | AS9: 0.090999066 | AT9: 0.087177829 | AU9: 0.096183949 | AV9: 0.092266478 | AW9: 0.088537449 | AX9: 0.097536209 | AY9: 0.093697543 | AZ9: 0.10297861 | BA9: 0.099045197 | BB9: 0.095299913 | BC9: 0.10454792 | BD9: 0.10069912 | BE9: 0.097040675 | BF9: 0.10627038 | BG9: 0.10249368 | BH9: 0.11201573 | BI9: 0.10814281 | BJ9: 0.10446023 | BK9: 0.11397606 | BL9: 0.11019522 | BM9: 0.10660673 | BN9: 0.11614644 | BO9: 0.1124437 | BP9: 0.10895033 | BQ9: 0.11850499 | BR9: 0.11489641 | BS9: 0.12475259 | BT9: 0.12103978 | BU9: 0.11752031 | BV9: 0.12739442 | BW9: 0.12375467 | BX9: 0.12032728 | BY9: 0.13023118 | BZ9: 0.12669152 | CA9: 0.12334617 | CB9: 0.13329989 | CC9: 0.1298603 | CD9: 0.12662207 | CE9: 0.1366177 | CF9: 0.13327922 | CG9: 0.14364949 | CH9: 0.14019778 | CI9: 0.13694038 | CJ9: 0.14736767 | CK9: 0.14401503 | CL9: 0.14086473 | CM9: 0.15134491 | CN9: 0.14809931 | CO9: 0.14505806 | CP9: 0.1556381 | CQ9: 0.15248652 | CR9: 0.14956232 | CS9: 0.16025228 | CT9: 0.15722078 | CU9: 0.1543936 | CV9: 0.16518463 | CW9: 0.16226722 | CX9: 0.15956016 | CY9: 0.17042325 | CZ9: 0.16762491 | DA9: 0.16503993 | DB9: 0.17604396 | DC9: 0.17336162 | DD9: 0.17092263 | DE9: 0.18217447 | DF9: 0.17967715 | DG9: 0.17740315 | DH9: 0.18906593 | DI9: 0.18679965 | DJ9: 0.18477571 | DK9: 0.19699474 | DL9: 0.19501162 | DM9: 0.19328384 | DN9: 0.20623359 | DO9: 0.20455863 | DP9: 0.20313406
A10: 0.01605042 | B10: 0.071257923 | C10: 0.080837587 | D10: 0.079841173 | E10: 0.078882404 | F10: 0.07796117 | G10: 0.077077582 | H10: 0.076231639 | I10: 0.086222931 | J10: 0.08539645 | K10: 0.084612317 | L10: 0.083870441 | M10: 0.08332182 | N10: 0.082792444 | O10: 0.093765635 | P10: 0.09336005 | Q10: 0.093023014 | R10: 0.092754524 | S10: 0.092554487 | T10: 0.092423 | U10: 0.092359961 | V10: 0.1049624 | W10: 0.090456303 | X10: 0.085875846 | Y10: 0.081467486 | Z10: 0.090725051 | AA10: 0.086215684 | AB10: 0.081889485 | AC10: 0.091103192 | AD10: 0.086678303 | AE10: 0.096119568 | AF10: 0.091608834 | AG10: 0.087271166 | AH10: 0.096692724 | AI10: 0.092255621 | AJ10: 0.10192995 | AK10: 0.097402002 | AL10: 0.093049218 | AM10: 0.10267856 | AN10: 0.098232963 | AO10: 0.093961851 | AP10: 0.10356239 | AQ10: 0.099184131 | AR10: 0.10904791 | AS10: 0.10457825 | AT10: 0.10028795 | AU10: 0.11013266 | AV10: 0.10575109 | AW10: 0.10154791 | AX10: 0.11139444 | AY10: 0.10708499 | AZ10: 0.11721599 | BA10: 0.11281037 | BB10: 0.10858413 | BC10: 0.11868905 | BD10: 0.11436457 | BE10: 0.11022149 | BF10: 0.12032029 | BG10: 0.11606392 | BH10: 0.12646812 | BI10: 0.1221165 | BJ10: 0.11794927 | BK10: 0.12836221 | BL10: 0.12410268 | BM10: 0.12002555 | BN10: 0.13047036 | BO10: 0.12628194 | BP10: 0.12229495 | BQ10: 0.13276171 | BR10: 0.12865947 | BS10: 0.13942882 | BT10: 0.13522732 | BU10: 0.13121121 | BV10: 0.14201048 | BW10: 0.13788005 | BX10: 0.13395603 | BY10: 0.14480706 | BZ10: 0.14077173 | CA10: 0.13692676 | CB10: 0.14784459 | CC10: 0.14390734 | CD10: 0.14016151 | CE10: 0.15112723 | CF10: 0.1472871 | CG10: 0.15862356 | CH10: 0.15466917 | CI10: 0.15090714 | CJ10: 0.16231262 | CK10: 0.15845832 | CL10: 0.15479841 | CM10: 0.16627376 | CN10: 0.1625285 | CO10: 0.15897864 | CP10: 0.17056783 | CQ10: 0.1669126 | CR10: 0.16347779 | CS10: 0.17518189 | CT10: 0.17163975 | CU10: 0.16829597 | CV10: 0.18010015 | CW10: 0.17667011 | CX10: 0.17344147 | CY10: 0.18533271 | CZ10: 0.18202676 | DA10: 0.1789252 | DB10: 0.19100338 | DC10: 0.18782442 | DD10: 0.18488587 | DE10: 0.19728682 | DF10: 0.19430988 | DG10: 0.19155431 | DH10: 0.2044492 | DI10: 0.20172531 | DJ10: 0.19923681 | DK10: 0.21275098 | DL10: 0.21032528 | DM10: 0.20814896 | DN10: 0.22243196 | DO10: 0.22032144 | DP10: 0.21846235
A11: 0.018056723 | B11: 0.081877426 | C11: 0.092077236 | D11: 0.09099667 | E11: 0.089958342 | F11: 0.088962442 | G11: 0.088008779 | H11: 0.087097357 | I11: 0.097827109 | J11: 0.096954581 | K11: 0.096130894 | L11: 0.095356058 | M11: 0.09478826 | N11: 0.0942453 | O11: 0.10613168 | P11: 0.10573904 | Q11: 0.10542435 | R11: 0.1051876 | S11: 0.1050278 | T11: 0.10494594 | U11: 0.10494102 | V11: 0.11863633 | W11: 0.1052692 | X11: 0.10024561 | Y11: 0.095394271 | Z11: 0.10541522 | AA11: 0.10045784 | AB11: 0.095689483 | AC11: 0.10567934 | AD11: 0.10080517 | AE11: 0.11104091 | AF11: 0.10607946 | AG11: 0.10129342 | AH11: 0.11151094 | AI11: 0.10661964 | AJ11: 0.11710357 | AK11: 0.1121141 | AL11: 0.10730205 | AM11: 0.11774288 | AN11: 0.11283458 | AO11: 0.10810472 | AP11: 0.11852344 | AQ11: 0.1136823 | AR11: 0.1243894 | AS11: 0.11945203 | AT11: 0.11469607 | AU11: 0.12539086 | AV11: 0.1205416 | AW11: 0.11587278 | AX11: 0.12657037 | AY11: 0.12178924 | AZ11: 0.13278536 | BA11: 0.12789904 | BB11: 0.12319715 | BC11: 0.13417018 | BD11: 0.12936701 | BE11: 0.1247473 | BF11: 0.1357252 | BG11: 0.13098916 | BH11: 0.14229851 | BI11: 0.13746119 | BJ11: 0.1328123 | BK11: 0.14413736 | BL11: 0.13939114 | BM11: 0.13483237 | BN11: 0.14618828 | BO11: 0.14150918 | BP11: 0.13703757 | BQ11: 0.14841942 | BR11: 0.14382253 | BS11: 0.15552605 | BT11: 0.15082686 | BU11: 0.14631811 | BV11: 0.15806454 | BW11: 0.15343543 | BX11: 0.14902078 | BY11: 0.16083394 | BZ11: 0.15629795 | CA11: 0.15195936 | CB11: 0.16384729 | CC11: 0.15940939 | CD11: 0.15516495 | CE11: 0.16709976 | CF11: 0.16275899 | CG11: 0.17508364 | CH11: 0.17061457 | CI11: 0.16634891 | CJ11: 0.17875658 | CK11: 0.17439161 | CL11: 0.17022609 | CM11: 0.1827166 | CN11: 0.17846269 | CO11: 0.17440922 | CP11: 0.18701856 | CQ11: 0.18285167 | CR11: 0.17891126 | CS11: 0.1916335 | CT11: 0.18757272 | CU11: 0.18371835 | CV11: 0.19654467 | CW11: 0.192597 | CX11: 0.18885578 | CY11: 0.20179618 | CZ11: 0.1979826 | DA11: 0.19438148 | DB11: 0.2075658 | DC11: 0.20389422 | DD11: 0.2004741 | DE11: 0.21406318 | DF11: 0.21061062 | DG11: 0.20739347 | DH11: 0.22155148 | DI11: 0.21837097 | DJ11: 0.21543391 | DK11: 0.23025823 | DL11: 0.22739094 | DM11: 0.22478008 | DN11: 0.24040933 | DO11: 0.23786524 | DP11: 0.23558565
A12: 0.020063025 | B12: 0.093206729 | C12: 0.10409648 | D12: 0.10292997 | E12: 0.10181338 | F12: 0.10074471 | G12: 0.099725577 | H12: 0.098755074 | I12: 0.11030879 | J12: 0.10939431 | K12: 0.10853677 | L12: 0.10773418 | M12: 0.1071534 | N12: 0.10660656 | O12: 0.11948742 | P12: 0.11911594 | Q12: 0.11883239 | R12: 0.11863578 | S12: 0.11852811 | T12: 0.11850738 | U12: 0.11857558 | V12: 0.13343226 | W12: 0.121349 | X12: 0.11585368 | Y12: 0.11053786 | Z12: 0.12137569 | AA12: 0.11594461 | AB12: 0.11071598 | AC12: 0.12153049 | AD12: 0.11618563 | AE12: 0.12726946 | AF12: 0.12182729 | AG12: 0.11657158 | AH12: 0.12763516 | AI12: 0.12226115 | AJ12: 0.13361219 | AK12: 0.128129 | AL12: 0.12283527 | AM12: 0.1341432 | AN12: 0.1287452 | AO12: 0.12353569 | AP12: 0.13482949 | AQ12: 0.12949866 | AR12: 0.14111289 | AS12: 0.13567381 | AT12: 0.13042918 | AU12: 0.14203207 | AV12: 0.13668311 | AW12: 0.13152664 | AX12: 0.1431283 | AY12: 0.13784449 | AZ12: 0.14977074 | BA12: 0.14437071 | BB12: 0.13916516 | BC12: 0.15107232 | BD12: 0.14575746 | BE12: 0.14063911 | BF12: 0.15256012 | BG12: 0.14731339 | BH12: 0.1596029 | BI12: 0.15424188 | BJ12: 0.14908233 | BK12: 0.16138751 | BL12: 0.1561176 | BM12: 0.15104818 | BN12: 0.1633812 | BO12: 0.15817543 | BP12: 0.15319319 | BQ12: 0.16555413 | BR12: 0.16043059 | BS12: 0.17315028 | BT12: 0.1679124 | BU12: 0.16288101 | BV12: 0.17565559 | BW12: 0.17048681 | BX12: 0.16555354 | BY12: 0.17840283 | BZ12: 0.17332817 | CA12: 0.16846796 | CB12: 0.18139399 | CC12: 0.17641743 | CD12: 0.17164838 | CE12: 0.18462029 | CF12: 0.17974188 | CG12: 0.19314371 | CH12: 0.18811697 | CI12: 0.18331168 | CJ12: 0.19681253 | CK12: 0.1918929 | CL12: 0.18718976 | CM12: 0.20078245 | CN12: 0.19597488 | CO12: 0.1913838 | CP12: 0.20509529 | CQ12: 0.20036775 | CR12: 0.19588874 | CS12: 0.20971011 | CT12: 0.20508568 | CU12: 0.20068672 | CV12: 0.21462619 | CW12: 0.21012189 | CX12: 0.20584009 | CY12: 0.21993364 | CZ12: 0.21557745 | DA12: 0.21145175 | DB12: 0.22586122 | DC12: 0.22165903 | DD12: 0.21773633 | DE12: 0.23263053 | DF12: 0.22866735 | DG12: 0.22496064 | DH12: 0.24048975 | DI12: 0.23681364 | DJ12: 0.23339801 | DK12: 0.24963248 | DL12: 0.2462786 | DM12: 0.2432042 | DN12: 0.2602957 | DO12: 0.25728005 | DP12: 0.25455494
A13: 0.022069328 | B13: 0.10531833 | C13: 0.11697313 | D13: 0.11572476 | E13: 0.11453132 | F13: 0.11339378 | G13: 0.11231217 | H13: 0.11128649 | I13: 0.12375147 | J13: 0.12280314 | K13: 0.12191575 | L13: 0.12109029 | M13: 0.12050164 | N13: 0.11995391 | O13: 0.13391116 | P13: 0.13356883 | Q13: 0.13332343 | R13: 0.13317696 | S13: 0.13312842 | T13: 0.13317881 | U13: 0.13332713 | V13: 0.14943318 | W13: 0.1387978 | X13: 0.13279475 | Y13: 0.12698224 | Z13: 0.13870916 | AA13: 0.13277137 | AB13: 0.12704808 | AC13: 0.13875664 | AD13: 0.13290709 | AE13: 0.14490901 | AF13: 0.13894912 | AG13: 0.13318774 | AH13: 0.14516837 | AI13: 0.13927467 | AJ13: 0.15156581 | AK13: 0.1455529 | AL13: 0.1397405 | AM13: 0.15199552 | AN13: 0.14606782 | AO13: 0.14034266 | AP13: 0.15259354 | AQ13: 0.14673303 | AR13: 0.15933438 | AS13: 0.15335659 | AT13: 0.1475843 | AU13: 0.16017428 | AV13: 0.15428362 | AW13: 0.1485975 | AX13: 0.16118623 | AY13: 0.15535674 | AZ13: 0.16830011 | BA13: 0.16234338 | BB13: 0.15659618 | BC13: 0.16952845 | BD13: 0.1636579 | BE13: 0.15799892 | BF13: 0.17095803 | BG13: 0.16515463 | BH13: 0.17851629 | BI13: 0.17258657 | BJ13: 0.16687237 | BK13: 0.18025066 | BL13: 0.17440806 | BM13: 0.168782 | BN13: 0.18218912 | BO13: 0.17640667 | BP13: 0.17086781 | BQ13: 0.18430785 | BR13: 0.17861164 | BS13: 0.19245451 | BT13: 0.18662894 | BU13: 0.18102492 | BV13: 0.19493865 | BW13: 0.18918019 | BX13: 0.18367429 | BY13: 0.19766871 | BZ13: 0.19200438 | CA13: 0.18656855 | CB13: 0.20064069 | CC13: 0.19507147 | CD13: 0.18972682 | CE13: 0.20384782 | CF13: 0.19837577 | CG13: 0.21297678 | CH13: 0.20734036 | CI13: 0.20193845 | CJ13: 0.21665648 | CK13: 0.21112619 | CL13: 0.20582944 | CM13: 0.22064629 | CN13: 0.21522407 | CO13: 0.21003739 | CP13: 0.22497302 | CQ13: 0.21962282 | CR13: 0.21454321 | CS13: 0.22959272 | CT13: 0.22434765 | CU13: 0.21934409 | CV13: 0.23454171 | CW13: 0.22942178 | CX13: 0.2245474 | CY13: 0.23995711 | CZ13: 0.23500029 | DA13: 0.23029703 | DB13: 0.24610464 | DC13: 0.24131683 | DD13: 0.23683557 | DE13: 0.25320288 | DF13: 0.24867009 | DG13: 0.2444168 | DH13: 0.26147303 | DI13: 0.2572363 | DJ13: 0.25328411 | DK13: 0.27108473 | DL13: 0.26718026 | DM13: 0.26358532 | DN13: 0.28232607 | DO13: 0.27878785 | DP13: 0.27556424
... A478: 0.955 | B478: 0.015493397 | C478: 0.016985252 | D478: 0.017579803 | E478: 0.018208462 | F478: 0.018870629 | G478: 0.019566902 | H478: 0.020297483 | I478: 0.021860321 | J478: 0.022550669 | K478: 0.023281123 | L478: 0.024052182 | M478: 0.02495596 | N478: 0.025886444 | O478: 0.027618858 | P478: 0.028524206 | Q478: 0.029475761 | R478: 0.030473222 | S478: 0.031517089 | T478: 0.032607062 | U478: 0.033743042 | V478: 0.034951874 | W478: 0.0181783 | X478: 0.0181856 | Y478: 0.0183198 | Z478: 0.0202953 | AA478: 0.0203653 | AB478: 0.020588 | AC478: 0.0224979 | AD478: 0.0226472 | AE478: 0.0246863 | AF478: 0.0247877 | AG478: 0.025024 | AH478: 0.0269818 | AI478: 0.0271539 | AJ478: 0.029255 | AK478: 0.0293619 | AL478: 0.0296051 | AM478: 0.0316201 | AN478: 0.0318157 | AO478: 0.0321417 | AP478: 0.0340906 | AQ478: 0.0343561 | AR478: 0.0364669 | AS478: 0.0366722 | AT478: 0.0370108 | AU478: 0.0390595 | AV478: 0.0393531 | AW478: 0.039774 | AX478: 0.0417658 | AY478: 0.0421253 | AZ478: 0.0442769 | BA478: 0.0445745 | BB478: 0.0450029 | BC478: 0.047096 | BD478: 0.04748 | BE478: 0.0479904 | BF478: 0.0500449 | BG478: 0.0504974 | BH478: 0.0527334 | BI478: 0.0531276 | BJ478: 0.0536529 | BK478: 0.0558489 | BL478: 0.05633 | BM478: 0.0569373 | BN478: 0.0590978 | BO478: 0.0596445 | BP478: 0.0603315 | BQ478: 0.0624723 | BR478: 0.0630903 | BS478: 0.0653985 | BT478: 0.0659738 | BU478: 0.0666777 | BV478: 0.0689755 | BW478: 0.0696227 | BX478: 0.0704145 | BY478: 0.0727224 | BZ478: 0.0734484 | CA478: 0.0743098 | CB478: 0.0766273 | CC478: 0.0774424 | CD478: 0.0783778 | CE478: 0.0806866 | CF478: 0.0815906 | CG478: 0.0840911 | CH478: 0.0849278 | CI478: 0.0859049 | CJ478: 0.0884322 | CK478: 0.0893668 | CL478: 0.0904291 | CM478: 0.0929814 | CN478: 0.0940182 | CO478: 0.0951807 | CP478: 0.0977754 | CQ478: 0.0988969 | CR478: 0.100162 | CS478: 0.102812 | CT478: 0.104028 | CU478: 0.105379 | CV478: 0.10809 | CW478: 0.109416 | CX478: 0.110867 | CY478: 0.113637 | CZ478: 0.115081 | DA478: 0.116651 | DB478: 0.119507 | DC478: 0.121057 | DD478: 0.122752 | DE478: 0.125712 | DF478: 0.127381 | DG478: 0.129188 | DH478: 0.132251 | DI478: 0.134053 | DJ478: 0.135985 | DK478: 0.139146 | DL478: 0.141097 | DM478: 0.143186 | DN478: 0.146524 | DO478: 0.148623 | DP478: 0.150877

Sheet Sheet2
A1: 0.04 | B1: 0.005

Sheet Sheet1 Copy
B1: 0 | C1: 0.002 | D1: 0.004 | E1: 0.006 | F1: 0.008 | G1: 0.01 | H1: 0.012 | I1: 0.014 | J1: 0.016 | K1: 0.018 | L1: 0.02 | M1: 0.022 | N1: 0.024 | O1: 0.026 | P1: 0.028 | Q1: 0.03 | R1: 0.032 | S1: 0.034 | T1: 0.036 | U1: 0.038 | V1: 0.039 | W1: =Sheet2!$A$1 + 0 * Sheet2!$B$1 -> 0.04 | X1: =Sheet2!$A$1 + 1 * Sheet2!$B$1 -> 0.045 | Y1: =Sheet2!$A$1 + 2 * Sheet2!$B$1 -> 0.05 | Z1: =Sheet2!$A$1 + 3 * Sheet2!$B$1 -> 0.055 | AA1: =Sheet2!$A$1 + 4 * Sheet2!$B$1 -> 0.06 | AB1: =Sheet2!$A$1 + 5 * Sheet2!$B$1 -> 0.065 | AC1: =Sheet2!$A$1 + 6 * Sheet2!$B$1 -> 0.07 | AD1: =Sheet2!$A$1 + 8 * Sheet2!$B$1 -> 0.08 | AE1: =Sheet2!$A$1 + 9 * Sheet2!$B$1 -> 0.085 | AF1: =Sheet2!$A$1 + 10 * Sheet2!$B$1 -> 0.09 | AG1: =Sheet2!$A$1 + 11 * Sheet2!$B$1 -> 0.095 | AH1: =Sheet2!$A$1 + 12 * Sheet2!$B$1 -> 0.1 | AI1: =Sheet2!$A$1 + 13 * Sheet2!$B$1 -> 0.105 | AJ1: =Sheet2!$A$1 + 14 * Sheet2!$B$1 -> 0.11 | AK1: =Sheet2!$A$1 + 15 * Sheet2!$B$1 -> 0.115 | AL1: =Sheet2!$A$1 + 16 * Sheet2!$B$1 -> 0.12 | AM1: =Sheet2!$A$1 + 17 * Sheet2!$B$1 -> 0.125 | AN1: =Sheet2!$A$1 + 18 * Sheet2!$B$1 -> 0.13 | AO1: =Sheet2!$A$1 + 19 * Sheet2!$B$1 -> 0.135 | AP1: =Sheet2!$A$1 + 20 * Sheet2!$B$1 -> 0.14 | AQ1: =Sheet2!$A$1 + 21 * Sheet2!$B$1 -> 0.145 | AR1: =Sheet2!$A$1 + 22 * Sheet2!$B$1 -> 0.15 | AS1: =Sheet2!$A$1 + 23 * Sheet2!$B$1 -> 0.155 | AT1: =Sheet2!$A$1 + 24 * Sheet2!$B$1 -> 0.16 | AU1: =Sheet2!$A$1 + 25 * Sheet2!$B$1 -> 0.165 | AV1: =Sheet2!$A$1 + 26 * Sheet2!$B$1 -> 0.17 | AW1: =Sheet2!$A$1 + 27 * Sheet2!$B$1 -> 0.175 | AX1: =Sheet2!$A$1 + 28 * Sheet2!$B$1 -> 0.18 | AY1: =Sheet2!$A$1 + 29 * Sheet2!$B$1 -> 0.185 | AZ1: =Sheet2!$A$1 + 30 * Sheet2!$B$1 -> 0.19 | BA1: 0.2 | BB1: 0.205 | BC1: 0.21 | BD1: 0.215 | BE1: 0.22 | BF1: 0.225 | BG1: 0.23 | BH1: 0.235 | BI1: 0.24 | BJ1: 0.245 | BK1: 0.25 | BL1: 0.256 | BM1: 0.27 | BN1: 0.275 | BO1: 0.28 | BP1: 0.285 | BQ1: 0.29 | BR1: 0.295 | BS1: 0.3 | BT1: 0.305 | BU1: 0.31 | BV1: 0.315 | BW1: 0.32 | BX1: 0.325 | BY1: 0.33 | BZ1: 0.335 | CA1: 0.34 | CB1: 0.345 | CC1: 0.35 | CD1: 0.355 | CE1: 0.36 | CF1: 0.365 | CG1: 0.37 | CH1: 0.375 | CI1: 0.38 | CJ1: 0.385 | CK1: 0.39 | CL1: 0.395 | CM1: 0.4 | CN1: 0.405 | CO1: 0.41 | CP1: 0.415 | CQ1: 0.42 | CR1: 0.425 | CS1: 0.43 | CT1: 0.435 | CU1: 0.44 | CV1: 0.445 | CW1: 0.45 | CX1: 0.455 | CY1: 0.46 | CZ1: 0.465 | DA1: 0.47 | DB1: 0.475 | DC1: 0.48 | DD1: 0.485 | DE1: 0.49 | DF1: 0.495 | DG1: 0.5 | DH1: 0.505 | DI1: 0.515 | DJ1: 0.52 | DK1: 0.525 | DL1: 0.53 | DM1: 0.535 | DN1: 0.54 | DO1: 0.545 | DP1: 0.55
A2: 0 | B2: 0.0181263 | C2: 0.0211045 | D2: 0.0213688 | E2: 0.0216786 | F2: 0.0220339 | G2: 0.0224347 | H2: 0.022881 | I2: 0.0259052 | J2: 0.0262569 | K2: 0.0266571 | L2: 0.0271059 | M2: 0.0277176 | N2: 0.0283668 | O2: 0.0315328 | P2: 0.0321007 | Q2: 0.032725 | R2: 0.0334056 | S2: 0.0341426 | T2: 0.0349359 | U2: 0.0357856 | V2: 0.0385572 | W2: 0.0192151 | X2: 0.0189459 | Y2: 0.0188451 | Z2: 0.0211929 | AA2: 0.0210046 | AB2: 0.0210158 | AC2: 0.0232745 | AD2: 0.0231872 | AE2: 0.0256118 | AF2: 0.0254547 | AG2: 0.0254745 | AH2: 0.027784 | AI2: 0.0277126 | AJ2: 0.0302032 | AK2: 0.0300433 | AL2: 0.0300614 | AM2: 0.0324369 | AN2: 0.0323866 | AO2: 0.0325083 | AP2: 0.0347976 | AQ2: 0.0348342 | AR2: 0.037334 | AS2: 0.0372874 | AT2: 0.037415 | AU2: 0.0398246 | AV2: 0.0398837 | AW2: 0.0401103 | AX2: 0.0424328 | AY2: 0.0425697 | AZ2: 0.0450954 | BA2: 0.0451454 | BB2: 0.0453664 | BC2: 0.0478101 | BD2: 0.0479647 | BE2: 0.0482853 | BF2: 0.0506749 | BG2: 0.0509113 | BH2: 0.0535346 | BI2: 0.0536872 | BJ2: 0.0540101 | BK2: 0.0565672 | BL2: 0.0568203 | BM2: 0.0572381 | BN2: 0.0597331 | BO2: 0.0600599 | BP2: 0.0605698 | BQ2: 0.0630254 | BR2: 0.063436 | BS2: 0.0661115 | BT2: 0.0664556 | BU2: 0.066967 | BV2: 0.0696225 | BW2: 0.0700485 | BX2: 0.0706615 | BY2: 0.0733147 | BZ2: 0.0738298 | CA2: 0.0745186 | CB2: 0.0771625 | CC2: 0.077776 | CD2: 0.0785451 | CE2: 0.0811569 | CF2: 0.0818685 | CG2: 0.0847269 | CH2: 0.0853388 | CI2: 0.0861295 | CJ2: 0.089011 | CK2: 0.0897328 | CL2: 0.0906184 | CM2: 0.0935188 | CN2: 0.0943532 | CO2: 0.0953485 | CP2: 0.0982812 | CQ2: 0.0992027 | CR2: 0.100307 | CS2: 0.103281 | CT2: 0.104301 | CU2: 0.105492 | CV2: 0.108517 | CW2: 0.109654 | CX2: 0.110949 | CY2: 0.114029 | CZ2: 0.115292 | DA2: 0.116714 | DB2: 0.119885 | DC2: 0.121256 | DD2: 0.122809 | DE2: 0.126082 | DF2: 0.127573 | DG2: 0.129235 | DH2: 0.132597 | DI2: 0.134221 | DJ2: 0.136007 | DK2: 0.139455 | DL2: 0.141231 | DM2: 0.14318 | DN2: 0.146826 | DO2: 0.148757 | DP2: 0.150877
A3: 0.002 | B3: 0.020884903 | C3: 0.024812348 | D3: 0.024873097 | E3: 0.024982438 | F3: 0.025140171 | G3: 0.025346498 | H3: 0.025601217 | I3: 0.029570179 | J3: 0.029714231 | K3: 0.029907377 | L3: 0.030149618 | M3: 0.03056524 | N3: 0.031020556 | O3: 0.035142842 | P3: 0.035504994 | Q3: 0.035926339 | R3: 0.036407178 | S3: 0.036947211 | T3: 0.037546538 | U3: 0.038205258 | V3: 0.042094726 | W3: 0.0229948 | X3: 0.022189668 | Y3: 0.021589986 | Z3: 0.024728769 | AA3: 0.024021561 | AB3: 0.023549498 | AC3: 0.026576449 | AD3: 0.025986963 | AE3: 0.029207546 | AF3: 0.028526229 | AG3: 0.028057158 | AH3: 0.031143016 | AI3: 0.030559715 | AJ3: 0.033862519 | AK3: 0.0331755 | AL3: 0.032701227 | AM3: 0.03587692 | AN3: 0.03531372 | AO3: 0.034959169 | AP3: 0.038036949 | AQ3: 0.037573466 | AR3: 0.040897289 | AS3: 0.040331181 | AT3: 0.039974518 | AU3: 0.043184507 | AV3: 0.042734711 | AW3: 0.042489464 | AX3: 0.04559523 | AY3: 0.045234649 | AZ3: 0.048587974 | BA3: 0.048122171 | BB3: 0.047863616 | BC3: 0.051124232 | BD3: 0.050776046 | BE3: 0.050631511 | BF3: 0.053826512 | BG3: 0.053570239 | BH3: 0.05703949 | BI3: 0.056676988 | BJ3: 0.056520333 | BK3: 0.059901451 | BL3: 0.05964856 | BM3: 0.059597618 | BN3: 0.06290412 | BO3: 0.062734443 | BP3: 0.062788419 | BQ3: 0.066047213 | BR3: 0.065977059 | BS3: 0.069510428 | BT3: 0.06934854 | BU3: 0.069390901 | BV3: 0.072895959 | BW3: 0.072822981 | BX3: 0.072976154 | BY3: 0.076460783 | BZ3: 0.076486917 | CA3: 0.076721396 | CB3: 0.080180399 | CC3: 0.080313043 | CD3: 0.080639138 | CE3: 0.084055729 | CF3: 0.084296688 | CG3: 0.088025771 | CH3: 0.088140697 | CI3: 0.088468668 | CJ3: 0.092220253 | CK3: 0.09245349 | CL3: 0.092887076 | CM3: 0.096647045 | CN3: 0.096998588 | CO3: 0.09754808 | CP3: 0.10132973 | CQ3: 0.10177007 | CR3: 0.10243447 | CS3: 0.10624961 | CT3: 0.10679797 | CU3: 0.10755337 | CV3: 0.11142252 | CW3: 0.11209589 | CX3: 0.11296531 | CY3: 0.11689346 | CZ3: 0.11769984 | DA3: 0.11870128 | DB3: 0.12271642 | DC3: 0.1236298 | DD3: 0.12476523 | DE3: 0.12886935 | DF3: 0.12990474 | DG3: 0.13114616 | DH3: 0.13533728 | DI3: 0.13651266 | DJ3: 0.1378861 | DK3: 0.14219125 | DL3: 0.14353066 | DM3: 0.14508512 | DN3: 0.14965637 | DO3: 0.1511718 | DP3: 0.15291429
A4: 0.004 | B4: 0.024800306 | C4: 0.029735897 | D4: 0.029585593 | E4: 0.029484476 | F4: 0.029432343 | G4: 0.029429295 | H4: 0.029475235 | I4: 0.034458358 | J4: 0.034388962 | K4: 0.034366854 | L4: 0.034392035 | M4: 0.03459658 | N4: 0.034840111 | O4: 0.040014584 | P4: 0.040168287 | Q4: 0.040382578 | R4: 0.040657256 | S4: 0.040992422 | T4: 0.041388075 | U4: 0.041844215 | V4: 0.047010251 | W4: 0.028240201 | X4: 0.026838837 | Y4: 0.025668671 | Z4: 0.029710938 | AA4: 0.028419221 | AB4: 0.027384196 | AC4: 0.031299198 | AD4: 0.030135426 | AE4: 0.034263192 | AF4: 0.032991058 | AG4: 0.031954116 | AH4: 0.035941531 | AI4: 0.03477523 | AJ4: 0.039006837 | AK4: 0.0377283 | AL4: 0.036685255 | AM4: 0.04078854 | AN4: 0.039640541 | AO4: 0.038726638 | AP4: 0.042727298 | AQ4: 0.041686233 | AR4: 0.045955678 | AS4: 0.044798962 | AT4: 0.043875537 | AU4: 0.048018114 | AV4: 0.046982622 | AW4: 0.046178428 | AX4: 0.05021216 | AY4: 0.049274198 | AZ4: 0.053590247 | BA4: 0.052535642 | BB4: 0.051713832 | BC4: 0.055934763 | BD4: 0.055004392 | BE4: 0.054305021 | BF4: 0.058453823 | BG4: 0.057621179 | BH4: 0.062071979 | BI4: 0.061117376 | BJ4: 0.060394166 | BK4: 0.064745302 | BL4: 0.06390522 | BM4: 0.063294937 | BN4: 0.06757054 | BO4: 0.066821185 | BP4: 0.066325238 | BQ4: 0.070552226 | BR4: 0.069915217 | BS4: 0.074459255 | BT4: 0.07370998 | BU4: 0.073192103 | BV4: 0.077702819 | BW4: 0.077046162 | BX4: 0.076644008 | BY4: 0.081120765 | BZ4: 0.080571033 | CA4: 0.080254391 | CB4: 0.084697497 | CC4: 0.084259986 | CD4: 0.084046077 | CE4: 0.088446358 | CF4: 0.088124776 | CG4: 0.092893041 | CH4: 0.092427693 | CI4: 0.092199336 | CJ4: 0.096990306 | CK4: 0.09664748 | CL4: 0.096533153 | CM4: 0.10132469 | CN4: 0.10110238 | CO4: 0.10110716 | CP4: 0.10591446 | CQ4: 0.10578415 | CR4: 0.10590795 | CS4: 0.11075022 | CT4: 0.11073694 | CU4: 0.11095674 | CV4: 0.11586204 | CW4: 0.11597978 | CX4: 0.11632262 | CY4: 0.12128893 | CZ4: 0.12154169 | DA4: 0.12202055 | DB4: 0.12706884 | DC4: 0.12742661 | DD4: 0.12804047 | DE4: 0.13316771 | DF4: 0.13365247 | DG4: 0.13437133 | DH4: 0.13959955 | DI4: 0.14023233 | DJ4: 0.1410962 | DK4: 0.1464855 | DL4: 0.14730132 | DM4: 0.14836624 | DN4: 0.15410374 | DO4: 0.15511961 | DP4: 0.15639159
A5: 0.006 | B5: 0.029936109 | C5: 0.035867645 | D5: 0.03551489 | E5: 0.035209214 | F5: 0.034950914 | G5: 0.034739793 | H5: 0.034575952 | I5: 0.040575036 | J5: 0.040303594 | K5: 0.040075931 | L5: 0.039892053 | M5: 0.03988942 | N5: 0.039922167 | O5: 0.046181526 | P5: 0.046143881 | Q5: 0.046166418 | R5: 0.046248934 | S5: 0.046391633 | T5: 0.046594413 | U5: 0.046857273 | V5: 0.053382277 | W5: 0.035041501 | X5: 0.033021905 | Y5: 0.031244757 | Z5: 0.036248007 | AA5: 0.034342882 | AB5: 0.032699494 | AC5: 0.037570547 | AD5: 0.035795488 | AE5: 0.040889138 | AF5: 0.038996888 | AG5: 0.037348375 | AH5: 0.042310847 | AI5: 0.040526645 | AJ5: 0.045749356 | AK5: 0.043851801 | AL5: 0.042197982 | AM5: 0.047301361 | AN5: 0.045532761 | AO5: 0.044009007 | AP5: 0.049013047 | AQ5: 0.047352099 | AR5: 0.052633567 | AS5: 0.050851943 | AT5: 0.049313155 | AU5: 0.054468621 | AV5: 0.052806933 | AW5: 0.051389092 | AX5: 0.056444489 | AY5: 0.054884147 | AZ5: 0.060242921 | BA5: 0.058562413 | BB5: 0.057125949 | BC5: 0.062395495 | BD5: 0.060838237 | BE5: 0.059525532 | BF5: 0.064723235 | BG5: 0.063264518 | BH5: 0.068776869 | BI5: 0.067189663 | BJ5: 0.0658455 | BK5: 0.071260053 | BL5: 0.06978738 | BM5: 0.068558555 | BN5: 0.073908961 | BO5: 0.072531128 | BP5: 0.071421157 | BQ5: 0.07672934 | BR5: 0.075471276 | BS5: 0.081121183 | BT5: 0.07973772 | BU5: 0.078599304 | BV5: 0.084216278 | BW5: 0.082925443 | BX5: 0.081902561 | BY5: 0.087480448 | BZ5: 0.08630125 | CA5: 0.085366387 | CB5: 0.090913496 | CC5: 0.089848629 | CD5: 0.089025815 | CE5: 0.094539688 | CF5: 0.093594264 | CG5: 0.099513212 | CH5: 0.09841739 | CI5: 0.097568604 | CJ5: 0.10351186 | CK5: 0.10253787 | CL5: 0.10180803 | CM5: 0.10774853 | CN5: 0.10689356 | CO5: 0.10628374 | CP5: 0.11224619 | CQ5: 0.11148522 | CR5: 0.11099642 | CS5: 0.11700183 | CT5: 0.11636591 | CU5: 0.11597812 | CV5: 0.12205856 | CW5: 0.12155567 | CX5: 0.12129793 | CY5: 0.12744039 | CZ5: 0.12707153 | DA5: 0.12694983 | DB5: 0.13316927 | DC5: 0.13290441 | DD5: 0.1329147 | DE5: 0.13921406 | DF5: 0.13908321 | DG5: 0.13920249 | DH5: 0.14563483 | DI5: 0.14566399 | DJ5: 0.1459473 | DK5: 0.15260574 | DL5: 0.15283598 | DM5: 0.15334136 | DN5: 0.16043911 | DO5: 0.16089741 | DP5: 0.16163088
A6: 0.008 | B6: 0.036269512 | C6: 0.043123894 | D6: 0.042589987 | E6: 0.042099852 | F6: 0.041653485 | G6: 0.041250791 | H6: 0.04089187 | I6: 0.047849715 | J6: 0.047402225 | K6: 0.046994509 | L6: 0.04662647 | M6: 0.04643876 | N6: 0.046280922 | O6: 0.053599468 | P6: 0.053404275 | Q6: 0.053267957 | R6: 0.053190612 | S6: 0.053172244 | T6: 0.05321275 | U6: 0.053312131 | V6: 0.061199702 | W6: 0.043395402 | X6: 0.040773173 | Y6: 0.038389843 | Z6: 0.044354076 | AA6: 0.041844042 | AB6: 0.039585292 | AC6: 0.045424096 | AD6: 0.043038751 | AE6: 0.049101884 | AF6: 0.046598817 | AG6: 0.044333233 | AH6: 0.050286762 | AI6: 0.047888561 | AJ6: 0.054106675 | AK6: 0.051600001 | AL6: 0.049330709 | AM6: 0.055446481 | AN6: 0.053059982 | AO6: 0.050913976 | AP6: 0.056941097 | AQ6: 0.054656966 | AR6: 0.060958056 | AS6: 0.058555724 | AT6: 0.056391774 | AU6: 0.062581128 | AV6: 0.060292545 | AW6: 0.058245556 | AX6: 0.064355019 | AY6: 0.062166596 | AZ6: 0.068585594 | BA6: 0.066280584 | BB6: 0.064216265 | BC6: 0.070558526 | BD6: 0.068369383 | BE6: 0.066422943 | BF6: 0.072701046 | BG6: 0.070606458 | BH6: 0.077198159 | BI6: 0.074977451 | BJ6: 0.072997133 | BK6: 0.079506304 | BL6: 0.077395739 | BM6: 0.075528674 | BN6: 0.081994581 | BO6: 0.079979171 | BP6: 0.078229476 | BQ6: 0.084665653 | BR6: 0.082770834 | BS6: 0.089553811 | BT6: 0.08752946 | BU6: 0.085749006 | BV6: 0.092505638 | BW6: 0.090570724 | BX6: 0.088901215 | BY6: 0.09562453 | BZ6: 0.093802066 | CA6: 0.092221182 | CB6: 0.098927095 | CC6: 0.097217672 | CD6: 0.095754154 | CE6: 0.10244412 | CF6: 0.10085355 | CG6: 0.10796328 | CH6: 0.10622559 | CI6: 0.10473107 | CJ6: 0.11186981 | CK6: 0.11024816 | CL6: 0.10887371 | CM6: 0.11601438 | CN6: 0.11450875 | CO6: 0.11325232 | CP6: 0.12042792 | CQ6: 0.1190183 | CR6: 0.11788389 | CS6: 0.12511945 | CT6: 0.12383887 | CU6: 0.12280749 | CV6: 0.13013008 | CW6: 0.12898055 | CX6: 0.12808324 | CY6: 0.13546786 | CZ6: 0.13444938 | DA6: 0.1336821 | DB6: 0.14114469 | DC6: 0.14022821 | DD6: 0.13959293 | DE6: 0.14715141 | DF6: 0.14637794 | DG6: 0.14585966 | DH6: 0.1536021 | DI6: 0.15300366 | DJ6: 0.1526704 | DK6: 0.16071799 | DL6: 0.16034164 | DM6: 0.16025148 | DN6: 0.16882848 | DO6: 0.16870722 | DP6: 0.16886618
A7: 0.01 | B7: 0.043704015 | C7: 0.051371742 | D7: 0.050685883 | E7: 0.05003969 | F7: 0.049433156 | G7: 0.048866388 | H7: 0.048339387 | I7: 0.056162994 | J7: 0.055574156 | K7: 0.055021786 | L7: 0.054506188 | M7: 0.0541692 | N7: 0.053856078 | O7: 0.06216961 | P7: 0.061860869 | Q7: 0.061610296 | R7: 0.06141789 | S7: 0.061283555 | T7: 0.061207388 | U7: 0.061189288 | V7: 0.070378828 | W7: 0.053223202 | X7: 0.050041641 | Y7: 0.047083929 | Z7: 0.053963245 | AA7: 0.050885703 | AB7: 0.048038891 | AC7: 0.054809445 | AD7: 0.051845914 | AE7: 0.05883743 | AF7: 0.055762746 | AG7: 0.052908691 | AH7: 0.059818978 | AI7: 0.056841976 | AJ7: 0.064012693 | AK7: 0.060935201 | AL7: 0.058078337 | AM7: 0.065167001 | AN7: 0.062197102 | AO7: 0.059451545 | AP7: 0.066467146 | AQ7: 0.063590132 | AR7: 0.070869645 | AS7: 0.067882604 | AT7: 0.065118292 | AU7: 0.072310135 | AV7: 0.069427656 | AW7: 0.06677252 | AX7: 0.073911049 | AY7: 0.071123345 | AZ7: 0.078565368 | BA7: 0.075669055 | BB7: 0.072998681 | BC7: 0.080379958 | BD7: 0.077588329 | BE7: 0.075025354 | BF7: 0.082355958 | BG7: 0.079651497 | BH7: 0.087286249 | BI7: 0.084464939 | BJ7: 0.081870166 | BK7: 0.089446755 | BL7: 0.086728899 | BM7: 0.084241492 | BN7: 0.091800701 | BO7: 0.089174313 | BP7: 0.086798195 | BQ7: 0.094343666 | BR7: 0.091832393 | BS7: 0.099713539 | BT7: 0.0970773 | BU7: 0.094671407 | BV7: 0.1025383 | BW7: 0.099986104 | BX7: 0.097683969 | BY7: 0.10553341 | BZ7: 0.10309108 | CA7: 0.10087598 | CB7: 0.10873049 | CC7: 0.10639622 | CD7: 0.10430019 | CE7: 0.11215965 | CF7: 0.10993944 | CG7: 0.11821235 | CH7: 0.11585698 | CI7: 0.11373084 | CJ7: 0.12203876 | CK7: 0.11979345 | CL7: 0.11778338 | CM7: 0.12610622 | CN7: 0.12397194 | CO7: 0.1220759 | CP7: 0.13045664 | CQ7: 0.12841837 | CR7: 0.12664337 | CS7: 0.13510206 | CT7: 0.13319484 | CU7: 0.13152386 | CV7: 0.14007759 | CW7: 0.13829644 | CX7: 0.13675754 | CY7: 0.14537532 | CZ7: 0.14371722 | DA7: 0.14230438 | DB7: 0.15100911 | DC7: 0.14945501 | DD7: 0.14817417 | DE7: 0.15700876 | DF7: 0.15560968 | DG7: 0.15445882 | DH7: 0.16354338 | DI7: 0.16233632 | DJ7: 0.1613925 | DK7: 0.17086924 | DL7: 0.1699053 | DM7: 0.1692246 | DN7: 0.17931385 | DO7: 0.17862802 | DP7: 0.17821647
A8: 0.012 | B8: 0.052100818 | C8: 0.060469891 | D8: 0.05966108 | E8: 0.058888828 | F8: 0.058153228 | G8: 0.057454286 | H8: 0.056791904 | I8: 0.065385673 | J8: 0.064690987 | K8: 0.064032063 | L8: 0.063408806 | M8: 0.06296464 | N8: 0.062539633 | O8: 0.071774952 | P8: 0.071398662 | Q8: 0.071081335 | R8: 0.070822768 | S8: 0.070623165 | T8: 0.070482525 | U8: 0.070400746 | V8: 0.080799853 | W8: 0.064407603 | X8: 0.06072121 | Y8: 0.057237914 | Z8: 0.064963113 | AA8: 0.061369163 | AB8: 0.057982789 | AC8: 0.065621694 | AD8: 0.062129177 | AE8: 0.069985376 | AF8: 0.066392175 | AG8: 0.062998449 | AH8: 0.070801793 | AI8: 0.067296991 | AJ8: 0.075353212 | AK8: 0.071755801 | AL8: 0.068358464 | AM8: 0.076351221 | AN8: 0.072848722 | AO8: 0.069549313 | AP8: 0.077486195 | AQ8: 0.074065898 | AR8: 0.082257234 | AS8: 0.078736685 | AT8: 0.075419011 | AU8: 0.083550242 | AV8: 0.080125567 | AW8: 0.076907684 | AX8: 0.085011879 | AY8: 0.081674094 | AZ8: 0.090069841 | BA8: 0.086632126 | BB8: 0.083400097 | BC8: 0.091750889 | BD8: 0.088406275 | BE8: 0.085269964 | BF8: 0.093586469 | BG8: 0.090320737 | BH8: 0.098931338 | BI8: 0.095560427 | BJ8: 0.092396799 | BK8: 0.10097691 | BL8: 0.097702659 | BM8: 0.094639311 | BN8: 0.10322652 | BO8: 0.10003746 | BP8: 0.097076713 | BQ8: 0.10566628 | BR8: 0.10258235 | BS8: 0.11148837 | BT8: 0.10829024 | BU8: 0.10530241 | BV8: 0.11420936 | BW8: 0.11108829 | BX8: 0.10819752 | BY8: 0.1171103 | BZ8: 0.1140943 | CA8: 0.11128857 | CB8: 0.12023019 | CC8: 0.11731826 | CD8: 0.11462563 | CE8: 0.12359418 | CF8: 0.12078933 | CG8: 0.13015142 | CH8: 0.12722438 | CI8: 0.12450761 | CJ8: 0.13391472 | CK8: 0.13109074 | CL8: 0.12848606 | CM8: 0.13792507 | CN8: 0.13521013 | CO8: 0.13271548 | CP8: 0.14223537 | CQ8: 0.13961645 | CR8: 0.13724084 | CS8: 0.14685767 | CT8: 0.14436481 | CU8: 0.14209123 | CV8: 0.15180811 | CW8: 0.14943533 | CX8: 0.14728785 | CY8: 0.15707079 | CZ8: 0.15481707 | DA8: 0.15279165 | DB8: 0.16268253 | DC8: 0.16053582 | DD8: 0.1586484 | DE8: 0.16872012 | DF8: 0.16674341 | DG8: 0.16500098 | DH8: 0.17540065 | DI8: 0.17363498 | DJ8: 0.17212261 | DK8: 0.18300149 | DL8: 0.18149896 | DM8: 0.18026572 | DN8: 0.19182522 | DO8: 0.19061883 | DP8: 0.18967376
A9: 0.014 | B9: 0.061319621 | C9: 0.070308239 | D9: 0.069399277 | E9: 0.068525966 | F9: 0.067688299 | G9: 0.066886384 | H9: 0.066120122 | I9: 0.075418652 | J9: 0.074648119 | K9: 0.07391524 | L9: 0.073220023 | M9: 0.07270838 | N9: 0.072214189 | O9: 0.082320894 | P9: 0.081916256 | Q9: 0.081573974 | R9: 0.081293846 | S9: 0.081075976 | T9: 0.080920363 | U9: 0.080826904 | V9: 0.092349779 | W9: 0.076839003 | X9: 0.072694178 | Y9: 0.068733 | Z9: 0.077240582 | AA9: 0.073176224 | AB9: 0.069301787 | AC9: 0.077746143 | AD9: 0.07377244 | AE9: 0.082435222 | AF9: 0.078370704 | AG9: 0.074487907 | AH9: 0.083119409 | AI9: 0.079134806 | AJ9: 0.088014731 | AK9: 0.083941501 | AL9: 0.080051091 | AM9: 0.088880741 | AN9: 0.084893143 | AO9: 0.081089982 | AP9: 0.089878844 | AQ9: 0.085964665 | AR9: 0.095006324 | AS9: 0.090999066 | AT9: 0.087177829 | AU9: 0.096183949 | AV9: 0.092266478 | AW9: 0.088537449 | AX9: 0.097536209 | AY9: 0.093697543 | AZ9: 0.10297861 | BA9: 0.099045197 | BB9: 0.095299913 | BC9: 0.10454792 | BD9: 0.10069912 | BE9: 0.097040675 | BF9: 0.10627038 | BG9: 0.10249368 | BH9: 0.11201573 | BI9: 0.10814281 | BJ9: 0.10446023 | BK9: 0.11397606 | BL9: 0.11019522 | BM9: 0.10660673 | BN9: 0.11614644 | BO9: 0.1124437 | BP9: 0.10895033 | BQ9: 0.11850499 | BR9: 0.11489641 | BS9: 0.12475259 | BT9: 0.12103978 | BU9: 0.11752031 | BV9: 0.12739442 | BW9: 0.12375467 | BX9: 0.12032728 | BY9: 0.13023118 | BZ9: 0.12669152 | CA9: 0.12334617 | CB9: 0.13329989 | CC9: 0.1298603 | CD9: 0.12662207 | CE9: 0.1366177 | CF9: 0.13327922 | CG9: 0.14364949 | CH9: 0.14019778 | CI9: 0.13694038 | CJ9: 0.14736767 | CK9: 0.14401503 | CL9: 0.14086473 | CM9: 0.15134491 | CN9: 0.14809931 | CO9: 0.14505806 | CP9: 0.1556381 | CQ9: 0.15248652 | CR9: 0.14956232 | CS9: 0.16025228 | CT9: 0.15722078 | CU9: 0.1543936 | CV9: 0.16518463 | CW9: 0.16226722 | CX9: 0.15956016 | CY9: 0.17042325 | CZ9: 0.16762491 | DA9: 0.16503993 | DB9: 0.17604396 | DC9: 0.17336162 | DD9: 0.17092263 | DE9: 0.18217447 | DF9: 0.17967715 | DG9: 0.17740315 | DH9: 0.18906593 | DI9: 0.18679965 | DJ9: 0.18477571 | DK9: 0.19699474 | DL9: 0.19501162 | DM9: 0.19328384 | DN9: 0.20623359 | DO9: 0.20455863 | DP9: 0.20313406
A10: 0.016 | B10: 0.071257923 | C10: 0.080837587 | D10: 0.079841173 | E10: 0.078882404 | F10: 0.07796117 | G10: 0.077077582 | H10: 0.076231639 | I10: 0.086222931 | J10: 0.08539645 | K10: 0.084612317 | L10: 0.083870441 | M10: 0.08332182 | N10: 0.082792444 | O10: 0.093765635 | P10: 0.09336005 | Q10: 0.093023014 | R10: 0.092754524 | S10: 0.092554487 | T10: 0.092423 | U10: 0.092359961 | V10: 0.1049624 | W10: 0.090456303 | X10: 0.085875846 | Y10: 0.081467486 | Z10: 0.090725051 | AA10: 0.086215684 | AB10: 0.081889485 | AC10: 0.091103192 | AD10: 0.086678303 | AE10: 0.096119568 | AF10: 0.091608834 | AG10: 0.087271166 | AH10: 0.096692724 | AI10: 0.092255621 | AJ10: 0.10192995 | AK10: 0.097402002 | AL10: 0.093049218 | AM10: 0.10267856 | AN10: 0.098232963 | AO10: 0.093961851 | AP10: 0.10356239 | AQ10: 0.099184131 | AR10: 0.10904791 | AS10: 0.10457825 | AT10: 0.10028795 | AU10: 0.11013266 | AV10: 0.10575109 | AW10: 0.10154791 | AX10: 0.11139444 | AY10: 0.10708499 | AZ10: 0.11721599 | BA10: 0.11281037 | BB10: 0.10858413 | BC10: 0.11868905 | BD10: 0.11436457 | BE10: 0.11022149 | BF10: 0.12032029 | BG10: 0.11606392 | BH10: 0.12646812 | BI10: 0.1221165 | BJ10: 0.11794927 | BK10: 0.12836221 | BL10: 0.12410268 | BM10: 0.12002555 | BN10: 0.13047036 | BO10: 0.12628194 | BP10: 0.12229495 | BQ10: 0.13276171 | BR10: 0.12865947 | BS10: 0.13942882 | BT10: 0.13522732 | BU10: 0.13121121 | BV10: 0.14201048 | BW10: 0.13788005 | BX10: 0.13395603 | BY10: 0.14480706 | BZ10: 0.14077173 | CA10: 0.13692676 | CB10: 0.14784459 | CC10: 0.14390734 | CD10: 0.14016151 | CE10: 0.15112723 | CF10: 0.1472871 | CG10: 0.15862356 | CH10: 0.15466917 | CI10: 0.15090714 | CJ10: 0.16231262 | CK10: 0.15845832 | CL10: 0.15479841 | CM10: 0.16627376 | CN10: 0.1625285 | CO10: 0.15897864 | CP10: 0.17056783 | CQ10: 0.1669126 | CR10: 0.16347779 | CS10: 0.17518189 | CT10: 0.17163975 | CU10: 0.16829597 | CV10: 0.18010015 | CW10: 0.17667011 | CX10: 0.17344147 | CY10: 0.18533271 | CZ10: 0.18202676 | DA10: 0.1789252 | DB10: 0.19100338 | DC10: 0.18782442 | DD10: 0.18488587 | DE10: 0.19728682 | DF10: 0.19430988 | DG10: 0.19155431 | DH10: 0.2044492 | DI10: 0.20172531 | DJ10: 0.19923681 | DK10: 0.21275098 | DL10: 0.21032528 | DM10: 0.20814896 | DN10: 0.22243196 | DO10: 0.22032144 | DP10: 0.21846235
A11: 0.018 | B11: 0.081877426 | C11: 0.092077236 | D11: 0.09099667 | E11: 0.089958342 | F11: 0.088962442 | G11: 0.088008779 | H11: 0.087097357 | I11: 0.097827109 | J11: 0.096954581 | K11: 0.096130894 | L11: 0.095356058 | M11: 0.09478826 | N11: 0.0942453 | O11: 0.10613168 | P11: 0.10573904 | Q11: 0.10542435 | R11: 0.1051876 | S11: 0.1050278 | T11: 0.10494594 | U11: 0.10494102 | V11: 0.11863633 | W11: 0.1052692 | X11: 0.10024561 | Y11: 0.095394271 | Z11: 0.10541522 | AA11: 0.10045784 | AB11: 0.095689483 | AC11: 0.10567934 | AD11: 0.10080517 | AE11: 0.11104091 | AF11: 0.10607946 | AG11: 0.10129342 | AH11: 0.11151094 | AI11: 0.10661964 | AJ11: 0.11710357 | AK11: 0.1121141 | AL11: 0.10730205 | AM11: 0.11774288 | AN11: 0.11283458 | AO11: 0.10810472 | AP11: 0.11852344 | AQ11: 0.1136823 | AR11: 0.1243894 | AS11: 0.11945203 | AT11: 0.11469607 | AU11: 0.12539086 | AV11: 0.1205416 | AW11: 0.11587278 | AX11: 0.12657037 | AY11: 0.12178924 | AZ11: 0.13278536 | BA11: 0.12789904 | BB11: 0.12319715 | BC11: 0.13417018 | BD11: 0.12936701 | BE11: 0.1247473 | BF11: 0.1357252 | BG11: 0.13098916 | BH11: 0.14229851 | BI11: 0.13746119 | BJ11: 0.1328123 | BK11: 0.14413736 | BL11: 0.13939114 | BM11: 0.13483237 | BN11: 0.14618828 | BO11: 0.14150918 | BP11: 0.13703757 | BQ11: 0.14841942 | BR11: 0.14382253 | BS11: 0.15552605 | BT11: 0.15082686 | BU11: 0.14631811 | BV11: 0.15806454 | BW11: 0.15343543 | BX11: 0.14902078 | BY11: 0.16083394 | BZ11: 0.15629795 | CA11: 0.15195936 | CB11: 0.16384729 | CC11: 0.15940939 | CD11: 0.15516495 | CE11: 0.16709976 | CF11: 0.16275899 | CG11: 0.17508364 | CH11: 0.17061457 | CI11: 0.16634891 | CJ11: 0.17875658 | CK11: 0.17439161 | CL11: 0.17022609 | CM11: 0.1827166 | CN11: 0.17846269 | CO11: 0.17440922 | CP11: 0.18701856 | CQ11: 0.18285167 | CR11: 0.17891126 | CS11: 0.1916335 | CT11: 0.18757272 | CU11: 0.18371835 | CV11: 0.19654467 | CW11: 0.192597 | CX11: 0.18885578 | CY11: 0.20179618 | CZ11: 0.1979826 | DA11: 0.19438148 | DB11: 0.2075658 | DC11: 0.20389422 | DD11: 0.2004741 | DE11: 0.21406318 | DF11: 0.21061062 | DG11: 0.20739347 | DH11: 0.22155148 | DI11: 0.21837097 | DJ11: 0.21543391 | DK11: 0.23025823 | DL11: 0.22739094 | DM11: 0.22478008 | DN11: 0.24040933 | DO11: 0.23786524 | DP11: 0.23558565
A12: 0.02 | B12: 0.093206729 | C12: 0.10409648 | D12: 0.10292997 | E12: 0.10181338 | F12: 0.10074471 | G12: 0.099725577 | H12: 0.098755074 | I12: 0.11030879 | J12: 0.10939431 | K12: 0.10853677 | L12: 0.10773418 | M12: 0.1071534 | N12: 0.10660656 | O12: 0.11948742 | P12: 0.11911594 | Q12: 0.11883239 | R12: 0.11863578 | S12: 0.11852811 | T12: 0.11850738 | U12: 0.11857558 | V12: 0.13343226 | W12: 0.121349 | X12: 0.11585368 | Y12: 0.11053786 | Z12: 0.12137569 | AA12: 0.11594461 | AB12: 0.11071598 | AC12: 0.12153049 | AD12: 0.11618563 | AE12: 0.12726946 | AF12: 0.12182729 | AG12: 0.11657158 | AH12: 0.12763516 | AI12: 0.12226115 | AJ12: 0.13361219 | AK12: 0.128129 | AL12: 0.12283527 | AM12: 0.1341432 | AN12: 0.1287452 | AO12: 0.12353569 | AP12: 0.13482949 | AQ12: 0.12949866 | AR12: 0.14111289 | AS12: 0.13567381 | AT12: 0.13042918 | AU12: 0.14203207 | AV12: 0.13668311 | AW12: 0.13152664 | AX12: 0.1431283 | AY12: 0.13784449 | AZ12: 0.14977074 | BA12: 0.14437071 | BB12: 0.13916516 | BC12: 0.15107232 | BD12: 0.14575746 | BE12: 0.14063911 | BF12: 0.15256012 | BG12: 0.14731339 | BH12: 0.1596029 | BI12: 0.15424188 | BJ12: 0.14908233 | BK12: 0.16138751 | BL12: 0.1561176 | BM12: 0.15104818 | BN12: 0.1633812 | BO12: 0.15817543 | BP12: 0.15319319 | BQ12: 0.16555413 | BR12: 0.16043059 | BS12: 0.17315028 | BT12: 0.1679124 | BU12: 0.16288101 | BV12: 0.17565559 | BW12: 0.17048681 | BX12: 0.16555354 | BY12: 0.17840283 | BZ12: 0.17332817 | CA12: 0.16846796 | CB12: 0.18139399 | CC12: 0.17641743 | CD12: 0.17164838 | CE12: 0.18462029 | CF12: 0.17974188 | CG12: 0.19314371 | CH12: 0.18811697 | CI12: 0.18331168 | CJ12: 0.19681253 | CK12: 0.1918929 | CL12: 0.18718976 | CM12: 0.20078245 | CN12: 0.19597488 | CO12: 0.1913838 | CP12: 0.20509529 | CQ12: 0.20036775 | CR12: 0.19588874 | CS12: 0.20971011 | CT12: 0.20508568 | CU12: 0.20068672 | CV12: 0.21462619 | CW12: 0.21012189 | CX12: 0.20584009 | CY12: 0.21993364 | CZ12: 0.21557745 | DA12: 0.21145175 | DB12: 0.22586122 | DC12: 0.22165903 | DD12: 0.21773633 | DE12: 0.23263053 | DF12: 0.22866735 | DG12: 0.22496064 | DH12: 0.24048975 | DI12: 0.23681364 | DJ12: 0.23339801 | DK12: 0.24963248 | DL12: 0.2462786 | DM12: 0.2432042 | DN12: 0.2602957 | DO12: 0.25728005 | DP12: 0.25455494
A13: 0.022 | B13: 0.10531833 | C13: 0.11697313 | D13: 0.11572476 | E13: 0.11453132 | F13: 0.11339378 | G13: 0.11231217 | H13: 0.11128649 | I13: 0.12375147 | J13: 0.12280314 | K13: 0.12191575 | L13: 0.12109029 | M13: 0.12050164 | N13: 0.11995391 | O13: 0.13391116 | P13: 0.13356883 | Q13: 0.13332343 | R13: 0.13317696 | S13: 0.13312842 | T13: 0.13317881 | U13: 0.13332713 | V13: 0.14943318 | W13: 0.1387978 | X13: 0.13279475 | Y13: 0.12698224 | Z13: 0.13870916 | AA13: 0.13277137 | AB13: 0.12704808 | AC13: 0.13875664 | AD13: 0.13290709 | AE13: 0.14490901 | AF13: 0.13894912 | AG13: 0.13318774 | AH13: 0.14516837 | AI13: 0.13927467 | AJ13: 0.15156581 | AK13: 0.1455529 | AL13: 0.1397405 | AM13: 0.15199552 | AN13: 0.14606782 | AO13: 0.14034266 | AP13: 0.15259354 | AQ13: 0.14673303 | AR13: 0.15933438 | AS13: 0.15335659 | AT13: 0.1475843 | AU13: 0.16017428 | AV13: 0.15428362 | AW13: 0.1485975 | AX13: 0.16118623 | AY13: 0.15535674 | AZ13: 0.16830011 | BA13: 0.16234338 | BB13: 0.15659618 | BC13: 0.16952845 | BD13: 0.1636579 | BE13: 0.15799892 | BF13: 0.17095803 | BG13: 0.16515463 | BH13: 0.17851629 | BI13: 0.17258657 | BJ13: 0.16687237 | BK13: 0.18025066 | BL13: 0.17440806 | BM13: 0.168782 | BN13: 0.18218912 | BO13: 0.17640667 | BP13: 0.17086781 | BQ13: 0.18430785 | BR13: 0.17861164 | BS13: 0.19245451 | BT13: 0.18662894 | BU13: 0.18102492 | BV13: 0.19493865 | BW13: 0.18918019 | BX13: 0.18367429 | BY13: 0.19766871 | BZ13: 0.19200438 | CA13: 0.18656855 | CB13: 0.20064069 | CC13: 0.19507147 | CD13: 0.18972682 | CE13: 0.20384782 | CF13: 0.19837577 | CG13: 0.21297678 | CH13: 0.20734036 | CI13: 0.20193845 | CJ13: 0.21665648 | CK13: 0.21112619 | CL13: 0.20582944 | CM13: 0.22064629 | CN13: 0.21522407 | CO13: 0.21003739 | CP13: 0.22497302 | CQ13: 0.21962282 | CR13: 0.21454321 | CS13: 0.22959272 | CT13: 0.22434765 | CU13: 0.21934409 | CV13: 0.23454171 | CW13: 0.22942178 | CX13: 0.2245474 | CY13: 0.23995711 | CZ13: 0.23500029 | DA13: 0.23029703 | DB13: 0.24610464 | DC13: 0.24131683 | DD13: 0.23683557 | DE13: 0.25320288 | DF13: 0.24867009 | DG13: 0.2444168 | DH13: 0.26147303 | DI13: 0.2572363 | DJ13: 0.25328411 | DK13: 0.27108473 | DL13: 0.26718026 | DM13: 0.26358532 | DN13: 0.28232607 | DO13: 0.27878785 | DP13: 0.27556424
